{
  "cveMetadata": {
    "cveId": "CVE-2025-58047",
    "assignerOrgId": "a0819718-46f1-4df5-94e2-005712e83aaa",
    "state": "PUBLISHED",
    "assignerShortName": "GitHub_M",
    "dateReserved": "2025-08-22T14:30:32.221Z",
    "datePublished": "2025-08-28T17:10:58.381Z",
    "dateUpdated": "2025-08-28T18:35:51.922Z"
  },
  "containers": {
    "cna": {
      "title": "Volto affected by possible DoS by invoking specific URL by anonymous user",
      "problemTypes": [
        {
          "descriptions": [
            {
              "cweId": "CWE-755",
              "lang": "en",
              "description": "CWE-755: Improper Handling of Exceptional Conditions",
              "type": "CWE"
            }
          ]
        }
      ],
      "metrics": [
        {
          "cvssV3_1": {
            "attackComplexity": "LOW",
            "attackVector": "NETWORK",
            "availabilityImpact": "HIGH",
            "baseScore": 7.5,
            "baseSeverity": "HIGH",
            "confidentialityImpact": "NONE",
            "integrityImpact": "NONE",
            "privilegesRequired": "NONE",
            "scope": "UNCHANGED",
            "userInteraction": "NONE",
            "vectorString": "CVSS:3.1/AV:N/AC:L/PR:N/UI:N/S:U/C:N/I:N/A:H",
            "version": "3.1"
          }
        }
      ],
      "references": [
        {
          "name": "https://github.com/plone/volto/security/advisories/GHSA-xjhf-7833-3pm5",
          "tags": [
            "x_refsource_CONFIRM"
          ],
          "url": "https://github.com/plone/volto/security/advisories/GHSA-xjhf-7833-3pm5"
        },
        {
          "name": "https://github.com/plone/volto/commit/2789a287ac45ad9039fb9161d465ba13241fff0a",
          "tags": [
            "x_refsource_MISC"
          ],
          "url": "https://github.com/plone/volto/commit/2789a287ac45ad9039fb9161d465ba13241fff0a"
        },
        {
          "name": "https://github.com/plone/volto/releases/tag/16.34.0",
          "tags": [
            "x_refsource_MISC"
          ],
          "url": "https://github.com/plone/volto/releases/tag/16.34.0"
        },
        {
          "name": "https://github.com/plone/volto/releases/tag/17.22.1",
          "tags": [
            "x_refsource_MISC"
          ],
          "url": "https://github.com/plone/volto/releases/tag/17.22.1"
        },
        {
          "name": "https://github.com/plone/volto/releases/tag/18.24.0",
          "tags": [
            "x_refsource_MISC"
          ],
          "url": "https://github.com/plone/volto/releases/tag/18.24.0"
        },
        {
          "name": "https://github.com/plone/volto/releases/tag/19.0.0-alpha.4",
          "tags": [
            "x_refsource_MISC"
          ],
          "url": "https://github.com/plone/volto/releases/tag/19.0.0-alpha.4"
        }
      ],
      "affected": [
        {
          "vendor": "plone",
          "product": "volto",
          "versions": [
            {
              "version": "< 16.34.0",
              "status": "affected"
            },
            {
              "version": ">= 17.0.0, < 17.22.1",
              "status": "affected"
            },
            {
              "version": ">= 18.0.0, < 18.24.0",
              "status": "affected"
            },
            {
              "version": ">= 19.0.0-alpha.1, < 19.0.0-alpha.4",
              "status": "affected"
            }
          ]
        }
      ],
      "providerMetadata": {
        "orgId": "a0819718-46f1-4df5-94e2-005712e83aaa",
        "shortName": "GitHub_M",
        "dateUpdated": "2025-08-28T17:10:58.381Z"
      },
      "descriptions": [
        {
          "lang": "en",
          "value": "Volto is a React based frontend for the Plone Content Management System. In versions from 19.0.0-alpha.1 to before 19.0.0-alpha.4, 18.0.0 to before 18.24.0, 17.0.0 to before 17.22.1, and prior to 16.34.0, an anonymous user could cause the NodeJS server part of Volto to quit with an error when visiting a specific URL. The problem has been patched in versions 16.34.0, 17.22.1, 18.24.0, and 19.0.0-alpha.4. To mitigate downtime, have setup automatically restart processes that quit with an error."
        }
      ],
      "source": {
        "advisory": "GHSA-xjhf-7833-3pm5",
        "discovery": "UNKNOWN"
      }
    },
    "adp": [
      {
        "metrics": [
          {
            "other": {
              "type": "ssvc",
              "content": {
                "timestamp": "2025-08-28T18:35:47.223133Z",
                "id": "CVE-2025-58047",
                "options": [
                  {
                    "Exploitation": "none"
                  },
                  {
                    "Automatable": "yes"
                  },
                  {
                    "Technical Impact": "partial"
                  }
                ],
                "role": "CISA Coordinator",
                "version": "2.0.3"
              }
            }
          }
        ],
        "title": "CISA ADP Vulnrichment",
        "providerMetadata": {
          "orgId": "134c704f-9b21-4f2e-91b3-4a467353bcc0",
          "shortName": "CISA-ADP",
          "dateUpdated": "2025-08-28T18:35:51.922Z"
        }
      }
    ]
  },
  "search": "解析验收测试文案"
}